Workbook

Sheet EL MÉTODO REBA

Sheet HOJA DE DATOS
P3: PUNTUACIÓN A | Q3: =IF((J17+J34+J47+J54+J57)=4,P9+H54,0) -> 3
P4: PUNTUACIÓN B | Q4: =IF((J71+J81+J97+J106+J109)=4,P75+H106,0) -> 1
B5: MÉTODO R.E.B.A. (HOJA DE DATOS): | P5: PUNTUACIÓN C | Q5: =SUM(S27:AD38) -> 2
P6: PUNTUACIÓN FINAL | Q6: =IF(Q5*M116<>0,Q5+Q117,0) -> 3
O9: TABLA A | P9: =SUM(O10:O69) -> 3
B10: Grupo A: Análisis de cuello, piernas y tronco | M10: 1_1_1 | N10: =AND((J17+J34+J47=3),H17=1,H34=1,H47=1) -> FALSE | O10: =IF(N10,1,0) -> 0
M11: 1_1_2 | N11: =AND((J17+J34+J47=3),H17=1,H34=1,H47=2) -> FALSE | O11: =IF(N11,2,0) -> 0 | S11: 1 | T11: 2 | U11: 3 | V11: 4 | W11: 5 | X11: 6 | Y11: 7 | Z11: 8 | AA11: 9 | AB11: 10 | AC11: 11 | AD11: 12
B12: CUELLO | M12: 1_1_3 | N12: =AND(($J$17+$J$34+$J$47=3),$H$17=1,$H$34=1,$H$47=3) -> FALSE | O12: =IF(N12,2,0) -> 0 | R12: 1 | S12: =AND($Q$3=1,$Q$4=1) -> FALSE | T12: =AND($Q$3=1,$Q$4=2) -> FALSE | U12: =AND($Q$3=1,$Q$4=3) -> FALSE | V12: =AND($Q$3=1,$Q$4=4) -> FALSE | W12: =AND($Q$3=1,$Q$4=5) -> FALSE | X12: =AND($Q$3=1,$Q$4=6) -> FALSE | Y12: =AND($Q$3=1,$Q$4=7) -> FALSE | Z12: =AND($Q$3=1,$Q$4=8) -> FALSE | AA12: =AND($Q$3=1,$Q$4=9) -> FALSE | AB12: =AND($Q$3=1,$Q$4=10) -> FALSE | AC12: =AND($Q$3=1,$Q$4=11) -> FALSE | AD12: =AND($Q$3=1,$Q$4=12) -> FALSE
M13: 1_1_4 | N13: =AND(($J$17+$J$34+$J$47=3),$H$17=1,$H$34=1,$H$47=4) -> FALSE | O13: =IF(N13,3,0) -> 0 | R13: 2 | S13: =AND($Q$3=2,$Q$4=1) -> FALSE | T13: =AND($Q$3=2,$Q$4=2) -> FALSE | U13: =AND($Q$3=2,$Q$4=3) -> FALSE | V13: =AND($Q$3=2,$Q$4=4) -> FALSE | W13: =AND($Q$3=2,$Q$4=5) -> FALSE | X13: =AND($Q$3=2,$Q$4=6) -> FALSE | Y13: =AND($Q$3=2,$Q$4=7) -> FALSE | Z13: =AND($Q$3=2,$Q$4=8) -> FALSE | AA13: =AND($Q$3=2,$Q$4=9) -> FALSE | AB13: =AND($Q$3=2,$Q$4=10) -> FALSE | AC13: =AND($Q$3=2,$Q$4=11) -> FALSE | AD13: =AND($Q$3=2,$Q$4=12) -> FALSE
M14: 1_1_5 | N14: =AND(($J$17+$J$34+$J$47=3),$H$17=1,$H$34=1,$H$47=5) -> FALSE | O14: =IF(N14,4,0) -> 0 | R14: 3 | S14: =AND($Q$3=3,$Q$4=1) -> TRUE | T14: =AND($Q$3=3,$Q$4=2) -> FALSE | U14: =AND($Q$3=3,$Q$4=3) -> FALSE | V14: =AND($Q$3=3,$Q$4=4) -> FALSE | W14: =AND($Q$3=3,$Q$4=5) -> FALSE | X14: =AND($Q$3=3,$Q$4=6) -> FALSE | Y14: =AND($Q$3=3,$Q$4=7) -> FALSE | Z14: =AND($Q$3=3,$Q$4=8) -> FALSE | AA14: =AND($Q$3=3,$Q$4=9) -> FALSE | AB14: =AND($Q$3=3,$Q$4=10) -> FALSE | AC14: =AND($Q$3=3,$Q$4=11) -> FALSE | AD14: =AND($Q$3=3,$Q$4=12) -> FALSE
M15: 1_2_1 | N15: =AND(($J$17+$J$34+$J$47=3),$H$17=1,$H$34=2,$H$47=1) -> FALSE | O15: =IF(N15,2,0) -> 0 | R15: 4 | S15: =AND($Q$3=4,$Q$4=1) -> FALSE | T15: =AND($Q$3=4,$Q$4=2) -> FALSE | U15: =AND($Q$3=4,$Q$4=3) -> FALSE | V15: =AND($Q$3=4,$Q$4=4) -> FALSE | W15: =AND($Q$3=4,$Q$4=5) -> FALSE | X15: =AND($Q$3=4,$Q$4=6) -> FALSE | Y15: =AND($Q$3=4,$Q$4=7) -> FALSE | Z15: =AND($Q$3=4,$Q$4=8) -> FALSE | AA15: =AND($Q$3=4,$Q$4=9) -> FALSE | AB15: =AND($Q$3=4,$Q$4=10) -> FALSE | AC15: =AND($Q$3=4,$Q$4=11) -> FALSE | AD15: =AND($Q$3=4,$Q$4=12) -> FALSE
M16: 1_2_2 | N16: =AND(($J$17+$J$34+$J$47=3),$H$17=1,$H$34=2,$H$47=2) -> FALSE | O16: =IF(N16,3,0) -> 0 | R16: 5 | S16: =AND($Q$3=5,$Q$4=1) -> FALSE | T16: =AND($Q$3=5,$Q$4=2) -> FALSE | U16: =AND($Q$3=5,$Q$4=3) -> FALSE | V16: =AND($Q$3=5,$Q$4=4) -> FALSE | W16: =AND($Q$3=5,$Q$4=5) -> FALSE | X16: =AND($Q$3=5,$Q$4=6) -> FALSE | Y16: =AND($Q$3=5,$Q$4=7) -> FALSE | Z16: =AND($Q$3=5,$Q$4=8) -> FALSE | AA16: =AND($Q$3=5,$Q$4=9) -> FALSE | AB16: =AND($Q$3=5,$Q$4=10) -> FALSE | AC16: =AND($Q$3=5,$Q$4=11) -> FALSE | AD16: =AND($Q$3=5,$Q$4=12) -> FALSE
H17: 3 | I17: =AND(H17<>1,H17<>2,H17<>3) -> FALSE | J17: =IF(I17,0,1) -> 1 | M17: 1_2_3 | N17: =AND(($J$17+$J$34+$J$47=3),$H$17=1,$H$34=2,$H$47=3) -> FALSE | O17: =IF(N17,4,0) -> 0 | R17: 6 | S17: =AND($Q$3=6,$Q$4=1) -> FALSE | T17: =AND($Q$3=6,$Q$4=2) -> FALSE | U17: =AND($Q$3=6,$Q$4=3) -> FALSE | V17: =AND($Q$3=6,$Q$4=4) -> FALSE | W17: =AND($Q$3=6,$Q$4=5) -> FALSE | X17: =AND($Q$3=6,$Q$4=6) -> FALSE | Y17: =AND($Q$3=6,$Q$4=7) -> FALSE | Z17: =AND($Q$3=6,$Q$4=8) -> FALSE | AA17: =AND($Q$3=6,$Q$4=9) -> FALSE | AB17: =AND($Q$3=6,$Q$4=10) -> FALSE | AC17: =AND($Q$3=6,$Q$4=11) -> FALSE | AD17: =AND($Q$3=6,$Q$4=12) -> FALSE
I18: =IF(I17," LA PUNTUACIÓN DEL CUELLO DEBE ESTAR EN UN RANGO DE 1 A 3."," ") | M18: 1_2_4 | N18: =AND(($J$17+$J$34+$J$47=3),$H$17=1,$H$34=2,$H$47=4) -> FALSE | O18: =IF(N18,5,0) -> 0 | R18: 7 | S18: =AND($Q$3=7,$Q$4=1) -> FALSE | T18: =AND($Q$3=7,$Q$4=2) -> FALSE | U18: =AND($Q$3=7,$Q$4=3) -> FALSE | V18: =AND($Q$3=7,$Q$4=4) -> FALSE | W18: =AND($Q$3=7,$Q$4=5) -> FALSE | X18: =AND($Q$3=7,$Q$4=6) -> FALSE | Y18: =AND($Q$3=7,$Q$4=7) -> FALSE | Z18: =AND($Q$3=7,$Q$4=8) -> FALSE | AA18: =AND($Q$3=7,$Q$4=9) -> FALSE | AB18: =AND($Q$3=7,$Q$4=10) -> FALSE | AC18: =AND($Q$3=7,$Q$4=11) -> FALSE | AD18: =AND($Q$3=7,$Q$4=12) -> FALSE
M19: 1_2_5 | N19: =AND(($J$17+$J$34+$J$47=3),$H$17=1,$H$34=2,$H$47=5) -> FALSE | O19: =IF(N19,6,0) -> 0 | R19: 8 | S19: =AND($Q$3=8,$Q$4=1) -> FALSE | T19: =AND($Q$3=8,$Q$4=2) -> FALSE | U19: =AND($Q$3=8,$Q$4=3) -> FALSE | V19: =AND($Q$3=8,$Q$4=4) -> FALSE | W19: =AND($Q$3=8,$Q$4=5) -> FALSE | X19: =AND($Q$3=8,$Q$4=6) -> FALSE | Y19: =AND($Q$3=8,$Q$4=7) -> FALSE | Z19: =AND($Q$3=8,$Q$4=8) -> FALSE | AA19: =AND($Q$3=8,$Q$4=9) -> FALSE | AB19: =AND($Q$3=8,$Q$4=10) -> FALSE | AC19: =AND($Q$3=8,$Q$4=11) -> FALSE | AD19: =AND($Q$3=8,$Q$4=12) -> FALSE
M20: 1_3_1 | N20: =AND(($J$17+$J$34+$J$47=3),$H$17=1,$H$34=3,$H$47=1) -> FALSE | O20: =IF(N20,3,0) -> 0 | R20: 9 | S20: =AND($Q$3=9,$Q$4=1) -> FALSE | T20: =AND($Q$3=9,$Q$4=2) -> FALSE | U20: =AND($Q$3=9,$Q$4=3) -> FALSE | V20: =AND($Q$3=9,$Q$4=4) -> FALSE | W20: =AND($Q$3=9,$Q$4=5) -> FALSE | X20: =AND($Q$3=9,$Q$4=6) -> FALSE | Y20: =AND($Q$3=9,$Q$4=7) -> FALSE | Z20: =AND($Q$3=9,$Q$4=8) -> FALSE | AA20: =AND($Q$3=9,$Q$4=9) -> FALSE | AB20: =AND($Q$3=9,$Q$4=10) -> FALSE | AC20: =AND($Q$3=9,$Q$4=11) -> FALSE | AD20: =AND($Q$3=9,$Q$4=12) -> FALSE
B21: PIERNAS | M21: 1_3_2 | N21: =AND(($J$17+$J$34+$J$47=3),$H$17=1,$H$34=3,$H$47=2) -> FALSE | O21: =IF(N21,4,0) -> 0 | R21: 10 | S21: =AND($Q$3=10,$Q$4=1) -> FALSE | T21: =AND($Q$3=10,$Q$4=2) -> FALSE | U21: =AND($Q$3=10,$Q$4=3) -> FALSE | V21: =AND($Q$3=10,$Q$4=4) -> FALSE | W21: =AND($Q$3=10,$Q$4=5) -> FALSE | X21: =AND($Q$3=10,$Q$4=6) -> FALSE | Y21: =AND($Q$3=10,$Q$4=7) -> FALSE | Z21: =AND($Q$3=10,$Q$4=8) -> FALSE | AA21: =AND($Q$3=10,$Q$4=9) -> FALSE | AB21: =AND($Q$3=10,$Q$4=10) -> FALSE | AC21: =AND($Q$3=10,$Q$4=11) -> FALSE | AD21: =AND($Q$3=10,$Q$4=12) -> FALSE
M22: 1_3_3 | N22: =AND(($J$17+$J$34+$J$47=3),$H$17=1,$H$34=3,$H$47=3) -> FALSE | O22: =IF(N22,5,0) -> 0 | R22: 11 | S22: =AND($Q$3=11,$Q$4=1) -> FALSE | T22: =AND($Q$3=11,$Q$4=2) -> FALSE | U22: =AND($Q$3=11,$Q$4=3) -> FALSE | V22: =AND($Q$3=11,$Q$4=4) -> FALSE | W22: =AND($Q$3=11,$Q$4=5) -> FALSE | X22: =AND($Q$3=11,$Q$4=6) -> FALSE | Y22: =AND($Q$3=11,$Q$4=7) -> FALSE | Z22: =AND($Q$3=11,$Q$4=8) -> FALSE | AA22: =AND($Q$3=11,$Q$4=9) -> FALSE | AB22: =AND($Q$3=11,$Q$4=10) -> FALSE | AC22: =AND($Q$3=11,$Q$4=11) -> FALSE | AD22: =AND($Q$3=11,$Q$4=12) -> FALSE
M23: 1_3_4 | N23: =AND(($J$17+$J$34+$J$47=3),$H$17=1,$H$34=3,$H$47=4) -> FALSE | O23: =IF(N23,6,0) -> 0 | R23: 12 | S23: =AND($Q$3=12,$Q$4=1) -> FALSE | T23: =AND($Q$3=12,$Q$4=2) -> FALSE | U23: =AND($Q$3=12,$Q$4=3) -> FALSE | V23: =AND($Q$3=12,$Q$4=4) -> FALSE | W23: =AND($Q$3=12,$Q$4=5) -> FALSE | X23: =AND($Q$3=12,$Q$4=6) -> FALSE | Y23: =AND($Q$3=12,$Q$4=7) -> FALSE | Z23: =AND($Q$3=12,$Q$4=8) -> FALSE | AA23: =AND($Q$3=12,$Q$4=9) -> FALSE | AB23: =AND($Q$3=12,$Q$4=10) -> FALSE | AC23: =AND($Q$3=12,$Q$4=11) -> FALSE | AD23: =AND($Q$3=12,$Q$4=12) -> FALSE
M24: 1_3_5 | N24: =AND(($J$17+$J$34+$J$47=3),$H$17=1,$H$34=3,$H$47=5) -> FALSE | O24: =IF(N24,7,0) -> 0
M25: 1_4_1 | N25: =AND(($J$17+$J$34+$J$47=3),$H$17=1,$H$34=4,$H$47=1) -> FALSE | O25: =IF(N25,4,0) -> 0
M26: 1_4_2 | N26: =AND(($J$17+$J$34+$J$47=3),$H$17=1,$H$34=4,$H$47=2) -> FALSE | O26: =IF(N26,5,0) -> 0 | S26: 1 | T26: 2 | U26: 3 | V26: 4 | W26: 5 | X26: 6 | Y26: 7 | Z26: 8 | AA26: 9 | AB26: 10 | AC26: 11 | AD26: 12
M27: 1_4_3 | N27: =AND(($J$17+$J$34+$J$47=3),$H$17=1,$H$34=4,$H$47=3) -> FALSE | O27: =IF(N27,6,0) -> 0 | R27: 1 | S27: =IF(S12,1,0) -> 0 | T27: =IF(T12,1,0) -> 0 | U27: =IF(U12,1,0) -> 0 | V27: =IF(V12,2,0) -> 0 | W27: =IF(W12,3,0) -> 0 | X27: =IF(X12,3,0) -> 0 | Y27: =IF(Y12,4,0) -> 0 | Z27: =IF(Z12,5,0) -> 0 | AA27: =IF(AA12,6,0) -> 0 | AB27: =IF(AB12,7,0) -> 0 | AC27: =IF(AC12,7,0) -> 0 | AD27: =IF(AD12,7,0) -> 0
M28: 1_4_4 | N28: =AND(($J$17+$J$34+$J$47=3),$H$17=1,$H$34=4,$H$47=4) -> FALSE | O28: =IF(N28,7,0) -> 0 | R28: 2 | S28: =IF(S13,1,0) -> 0 | T28: =IF(T13,2,0) -> 0 | U28: =IF(U13,2,0) -> 0 | V28: =IF(V13,3,0) -> 0 | W28: =IF(W13,4,0) -> 0 | X28: =IF(X13,4,0) -> 0 | Y28: =IF(Y13,5,0) -> 0 | Z28: =IF(Z13,6,0) -> 0 | AA28: =IF(AA13,6,0) -> 0 | AB28: =IF(AB13,7,0) -> 0 | AC28: =IF(AC13,7,0) -> 0 | AD28: =IF(AD13,8,0) -> 0
M29: 1_4_5 | N29: =AND(($J$17+$J$34+$J$47=3),$H$17=1,$H$34=4,$H$47=5) -> FALSE | O29: =IF(N29,8,0) -> 0 | R29: 3 | S29: =IF(S14,2,0) -> 2 | T29: =IF(T14,3,0) -> 0 | U29: =IF(U14,3,0) -> 0 | V29: =IF(V14,3,0) -> 0 | W29: =IF(W14,4,0) -> 0 | X29: =IF(X14,5,0) -> 0 | Y29: =IF(Y14,6,0) -> 0 | Z29: =IF(Z14,7,0) -> 0 | AA29: =IF(AA14,7,0) -> 0 | AB29: =IF(AB14,8,0) -> 0 | AC29: =IF(AC14,8,0) -> 0 | AD29: =IF(AD14,8,0) -> 0
M30: 2_1_1 | N30: =AND(($J$17+$J$34+$J$47=3),$H$17=2,$H$34=1,$H$47=1) -> FALSE | O30: =IF(N30,1,0) -> 0 | R30: 4 | S30: =IF(S15,3,0) -> 0 | T30: =IF(T15,4,0) -> 0 | U30: =IF(U15,4,0) -> 0 | V30: =IF(V15,4,0) -> 0 | W30: =IF(W15,5,0) -> 0 | X30: =IF(X15,6,0) -> 0 | Y30: =IF(Y15,7,0) -> 0 | Z30: =IF(Z15,8,0) -> 0 | AA30: =IF(AA15,8,0) -> 0 | AB30: =IF(AB15,9,0) -> 0 | AC30: =IF(AC15,9,0) -> 0 | AD30: =IF(AD15,9,0) -> 0
M31: 2_1_2 | N31: =AND(($J$17+$J$34+$J$47=3),$H$17=2,$H$34=1,$H$47=2) -> FALSE | O31: =IF(N31,3,0) -> 0 | R31: 5 | S31: =IF(S16,4,0) -> 0 | T31: =IF(T16,4,0) -> 0 | U31: =IF(U16,4,0) -> 0 | V31: =IF(V16,5,0) -> 0 | W31: =IF(W16,6,0) -> 0 | X31: =IF(X16,7,0) -> 0 | Y31: =IF(Y16,8,0) -> 0 | Z31: =IF(Z16,8,0) -> 0 | AA31: =IF(AA16,9,0) -> 0 | AB31: =IF(AB16,9,0) -> 0 | AC31: =IF(AC16,9,0) -> 0 | AD31: =IF(AD16,9,0) -> 0
M32: 2_1_3 | N32: =AND(($J$17+$J$34+$J$47=3),$H$17=2,$H$34=1,$H$47=3) -> FALSE | O32: =IF(N32,4,0) -> 0 | R32: 6 | S32: =IF(S17,6,0) -> 0 | T32: =IF(T17,6,0) -> 0 | U32: =IF(U17,6,0) -> 0 | V32: =IF(V17,7,0) -> 0 | W32: =IF(W17,8,0) -> 0 | X32: =IF(X17,8,0) -> 0 | Y32: =IF(Y17,9,0) -> 0 | Z32: =IF(Z17,9,0) -> 0 | AA32: =IF(AA17,10,0) -> 0 | AB32: =IF(AB17,10,0) -> 0 | AC32: =IF(AC17,10,0) -> 0 | AD32: =IF(AD17,10,0) -> 0
M33: 2_1_4 | N33: =AND(($J$17+$J$34+$J$47=3),$H$17=2,$H$34=1,$H$47=4) -> FALSE | O33: =IF(N33,5,0) -> 0 | R33: 7 | S33: =IF(S18,7,0) -> 0 | T33: =IF(T18,7,0) -> 0 | U33: =IF(U18,7,0) -> 0 | V33: =IF(V18,8,0) -> 0 | W33: =IF(W18,9,0) -> 0 | X33: =IF(X18,9,0) -> 0 | Y33: =IF(Y18,9,0) -> 0 | Z33: =IF(Z18,10,0) -> 0 | AA33: =IF(AA18,10,0) -> 0 | AB33: =IF(AB18,11,0) -> 0 | AC33: =IF(AC18,11,0) -> 0 | AD33: =IF(AD18,11,0) -> 0
H34: 1 | I34: =AND(H34<>1,H34<>2,H34<>3,H34<>4) -> FALSE | J34: =IF(I34,0,1) -> 1 | M34: 2_1_5 | N34: =AND(($J$17+$J$34+$J$47=3),$H$17=2,$H$34=1,$H$47=5) -> FALSE | O34: =IF(N34,6,0) -> 0 | R34: 8 | S34: =IF(S19,8,0) -> 0 | T34: =IF(T19,8,0) -> 0 | U34: =IF(U19,8,0) -> 0 | V34: =IF(V19,9,0) -> 0 | W34: =IF(W19,10,0) -> 0 | X34: =IF(X19,10,0) -> 0 | Y34: =IF(Y19,10,0) -> 0 | Z34: =IF(Z19,10,0) -> 0 | AA34: =IF(AA19,10,0) -> 0 | AB34: =IF(AB19,11,0) -> 0 | AC34: =IF(AC19,11,0) -> 0 | AD34: =IF(AD19,11,0) -> 0
I35: =IF(I34," LA PUNTUACIÓN DE LAS PIERNAS DEBE ESTAR EN UN RANGO DE 1 A 4."," ") | M35: 2_2_1 | N35: =AND(($J$17+$J$34+$J$47=3),$H$17=2,$H$34=2,$H$47=1) -> FALSE | O35: =IF(N35,2,0) -> 0 | R35: 9 | S35: =IF(S20,9,0) -> 0 | T35: =IF(T20,9,0) -> 0 | U35: =IF(U20,9,0) -> 0 | V35: =IF(V20,10,0) -> 0 | W35: =IF(W20,10,0) -> 0 | X35: =IF(X20,10,0) -> 0 | Y35: =IF(Y20,11,0) -> 0 | Z35: =IF(Z20,11,0) -> 0 | AA35: =IF(AA20,11,0) -> 0 | AB35: =IF(AB20,12,0) -> 0 | AC35: =IF(AC20,12,0) -> 0 | AD35: =IF(AD20,12,0) -> 0
M36: 2_2_2 | N36: =AND(($J$17+$J$34+$J$47=3),$H$17=2,$H$34=2,$H$47=2) -> FALSE | O36: =IF(N36,4,0) -> 0 | R36: 10 | S36: =IF(S21,10,0) -> 0 | T36: =IF(T21,10,0) -> 0 | U36: =IF(U21,10,0) -> 0 | V36: =IF(V21,11,0) -> 0 | W36: =IF(W21,11,0) -> 0 | X36: =IF(X21,11,0) -> 0 | Y36: =IF(Y21,11,0) -> 0 | Z36: =IF(Z21,12,0) -> 0 | AA36: =IF(AA21,12,0) -> 0 | AB36: =IF(AB21,12,0) -> 0 | AC36: =IF(AC21,12,0) -> 0 | AD36: =IF(AD21,12,0) -> 0
M37: 2_2_3 | N37: =AND(($J$17+$J$34+$J$47=3),$H$17=2,$H$34=2,$H$47=3) -> FALSE | O37: =IF(N37,5,0) -> 0 | R37: 11 | S37: =IF(S22,11,0) -> 0 | T37: =IF(T22,11,0) -> 0 | U37: =IF(U22,11,0) -> 0 | V37: =IF(V22,11,0) -> 0 | W37: =IF(W22,12,0) -> 0 | X37: =IF(X22,12,0) -> 0 | Y37: =IF(Y22,12,0) -> 0 | Z37: =IF(Z22,12,0) -> 0 | AA37: =IF(AA22,12,0) -> 0 | AB37: =IF(AB22,12,0) -> 0 | AC37: =IF(AC22,12,0) -> 0 | AD37: =IF(AD22,12,0) -> 0
B38: TRONCO | M38: 2_2_4 | N38: =AND(($J$17+$J$34+$J$47=3),$H$17=2,$H$34=2,$H$47=4) -> FALSE | O38: =IF(N38,6,0) -> 0 | R38: 12 | S38: =IF(S23,12,0) -> 0 | T38: =IF(T23,12,0) -> 0 | U38: =IF(U23,12,0) -> 0 | V38: =IF(V23,12,0) -> 0 | W38: =IF(W23,12,0) -> 0 | X38: =IF(X23,12,0) -> 0 | Y38: =IF(Y23,12,0) -> 0 | Z38: =IF(Z23,12,0) -> 0 | ... AD38: =IF(AD23,12,0) -> 0
M39: 2_2_5 | N39: =AND(($J$17+$J$34+$J$47=3),$H$17=2,$H$34=2,$H$47=5) -> FALSE | O39: =IF(N39,7,0) -> 0
M40: 2_3_1 | N40: =AND(($J$17+$J$34+$J$47=3),$H$17=2,$H$34=3,$H$47=1) -> FALSE | O40: =IF(N40,3,0) -> 0
M41: 2_3_2 | N41: =AND(($J$17+$J$34+$J$47=3),$H$17=2,$H$34=3,$H$47=2) -> FALSE | O41: =IF(N41,5,0) -> 0
M42: 2_3_3 | N42: =AND(($J$17+$J$34+$J$47=3),$H$17=2,$H$34=3,$H$47=3) -> FALSE | O42: =IF(N42,6,0) -> 0
M43: 2_3_4 | N43: =AND(($J$17+$J$34+$J$47=3),$H$17=2,$H$34=3,$H$47=4) -> FALSE | O43: =IF(N43,7,0) -> 0
M44: 2_3_5 | N44: =AND(($J$17+$J$34+$J$47=3),$H$17=2,$H$34=3,$H$47=5) -> FALSE | O44: =IF(N44,8,0) -> 0
...

Sheet NIVEL DE RIESGO Y ACCIÓN
B2: =IF('HOJA DE DATOS'!Q6=0,"EXISTEN DATOS ERRONEOS O FALTAN DATOS POR RELLENAR. VUELVA A LA HOJA DE DATOS."," ")
B5: RESUMEN DE DATOS:
B7: Grupo A: Análisis de cuello, piernas y tronco
B9: PUNTUACIÓN CUELLO(1-3): | F9: =IF('HOJA DE DATOS'!Q6<>0,'HOJA DE DATOS'!H17," ") -> 3
B10: PUNTUACIÓN PIERNAS(1-4): | F10: =IF('HOJA DE DATOS'!Q6<>0,'HOJA DE DATOS'!H34," ") -> 1
B11: PUNTUACIÓN TRONCO(1-5): | F11: =IF('HOJA DE DATOS'!Q6<>0,'HOJA DE DATOS'!H47," ") -> 1
B12: PUNTUACIÓN CARGA/FUERZA(0-3): | F12: =IF('HOJA DE DATOS'!Q6<>0,'HOJA DE DATOS'!H54," ") -> 0
B14: Grupo B: Análisis de brazos, antebrazos y muñecas
B16: PUNTUACIÓN ANTEBRAZOS(1-2): | F16: =IF('HOJA DE DATOS'!Q6<>0,'HOJA DE DATOS'!H71," ") -> 1
B17: PUNTUACIÓN MUÑECAS(1-3): | F17: =IF('HOJA DE DATOS'!Q6<>0,'HOJA DE DATOS'!H81," ") -> 1
B18: PUNTUACIÓN BRAZOS(1-6): | F18: =IF('HOJA DE DATOS'!Q6<>0,'HOJA DE DATOS'!H97," ") -> 1
B19: PUNTUACIÓN AGARRE(0-3): | F19: =IF('HOJA DE DATOS'!Q6<>0,'HOJA DE DATOS'!H106," ") -> 0
B21: Actividad muscular:
B23: =IF(H23=0,"No hay partes del cuerpo estáticas",IF(H23=1,"Una o más partes del cuerpo permanecen estáticas",IF(H23=2," "))) -> Una o más partes del cuerpo permanecen estáticas | H23: =IF(AND('HOJA DE DATOS'!J112*'HOJA DE DATOS'!J116*'HOJA DE DATOS'!J120*'HOJA DE DATOS'!Q6<>0,'HOJA DE DATOS'!L112=1),1,IF(AND('HOJA DE DATOS'!J112*'HOJA DE DATOS'!J116*'HOJA DE DATOS'!J120*'HOJA DE DATOS'!Q6<>0,'HOJA DE DATOS'!L112=0),0,IF('HOJA DE DATOS'!J112*'HOJA DE DATOS'!J116*'HOJA DE DATOS'!J120*'HOJA DE DATOS'!Q6=0,2))) -> 1
B24: =IF(H24=0,"No existen movimientos repetitivos",IF(H24=1,"Existen movimientos repetitivos",IF(H24=2," "))) -> No existen movimientos repetitivos | H24: =IF(AND('HOJA DE DATOS'!J112*'HOJA DE DATOS'!J116*'HOJA DE DATOS'!J120*'HOJA DE DATOS'!Q6<>0,'HOJA DE DATOS'!L116=1),1,IF(AND('HOJA DE DATOS'!J112*'HOJA DE DATOS'!J116*'HOJA DE DATOS'!J120*'HOJA DE DATOS'!Q6<>0,'HOJA DE DATOS'!L116=0),0,IF('HOJA DE DATOS'!J112*'HOJA DE DATOS'!J116*'HOJA DE DATOS'!J120*'HOJA DE DATOS'!Q6=0,2))) -> 0
B25: =IF(H25=0,"No se producen cambios posturales importantes ni posturas inestables",IF(H25=1,"Se producen cambios posturales importantes o posturas inestables",IF(H25=2," "))) -> No se producen cambios posturales importantes ni posturas inestables | H25: =IF(AND('HOJA DE DATOS'!J112*'HOJA DE DATOS'!J116*'HOJA DE DATOS'!J120*'HOJA DE DATOS'!Q6<>0,'HOJA DE DATOS'!L120=1),1,IF(AND('HOJA DE DATOS'!J112*'HOJA DE DATOS'!J116*'HOJA DE DATOS'!J120*'HOJA DE DATOS'!Q6<>0,'HOJA DE DATOS'!L120=0),0,IF('HOJA DE DATOS'!J112*'HOJA DE DATOS'!J116*'HOJA DE DATOS'!J120*'HOJA DE DATOS'!Q6=0,2))) -> 0
B26: =IF('HOJA DE DATOS'!Q6=0,"EXISTEN DATOS ERRONEOS O FALTAN DATOS POR RELLENAR. VUELVA A LA HOJA DE DATOS."," ")
B30: NIVELES DE RIESGO Y ACCIÓN:
B32: Puntuación final REBA(1-15) | E32: =IF('HOJA DE DATOS'!Q6<>0,'HOJA DE DATOS'!Q6," ") -> 3
B34: Nivel de acción(0-4) | E34: =IF(E32=1,0,IF(OR(E32=2,E32=3),1,IF(AND(E32>3,E32<8),2,IF(AND(E32>7,E32<11),3,IF(AND(E32>10,E32<16),4," "))))) -> 1
B36: Nivel de riesgo | E36: =IF(E34=0,"Inapreciable",IF(E34=1,"Bajo",IF(E34=2,"Medio",IF(E34=3,"Alto",IF(E34=4,"Muy alto", " "))))) -> Bajo
B38: Actuación | E38: =IF(E34=0,"No es necesaria actuación",IF(E34=1,"Puede ser necesaria la actuación",IF(E34=2,"Es necesaria la actuación",IF(E34=3,"Es necesaria la actuación cuanto antes",IF(E34=4,"Es necesaria la actuación de inmediato", " "))))) -> Puede ser necesaria la actuación

Sheet EJEMPLO DE APLICACIÓN
